Workbook

Sheet index
A1: 1 | B1: Alec Reed Academy
A2: 2 | B2: Groups
A3: 3 | B3: quali_schedule
A4: 4 | B4: quali_score
A5: 5 | B5: quali_results
A6: 6 | B6: knockout_score
A7: 7 | B7: final_results

Sheet attendance
A1: Group | B1: Team | C1: Player1 | D1: Attendance | E1: Player2 | F1: Attendance | G1: Total
A2: Group A | B2: E16/E17 | C2: nalukoK | E2: levurihT | G2: =IF(AND(D2=1,F2=1),1,"")
A3: Group A | B3: E82 | C3: lisaB | E3: najararamuK | G3: =IF(AND(D3=1,F3=1),1,"")
A4: Group A | B4: E91B | C4: amraD | E4: upnA | G4: =IF(AND(D4=1,F4=1),1,"")
A5: Group A | B5: E97 | C5: hsenahD | E5: nahticrahT | G5: =IF(AND(D5=1,F5=1),1,"")
A6: Group A | B6: E99 | C6: maK | E6: ivaR | G6: =IF(AND(D6=1,F6=1),1,"")
G7: =SUM(G2:G6) -> 0
A8: Group B | B8: E00 | C8: atteM | E8: igiV | G8: =IF(AND(D8=1,F8=1),1,"")
A9: Group B | B9: E01B | C9: napalaK | E9: ardnejaK | G9: =IF(AND(D9=1,F9=1),1,"")
A10: Group B | B10: E85/E88 | C10: yoroL | E10: nardneluK | G10: =IF(AND(D10=1,F10=1),1,"")
A11: Group B | B11: E91C | C11: lugaN | E11: merP | G11: =IF(AND(D11=1,F11=1),1,"")
A12: Group B | B12: S95 | C12: nahtusaviS | E12: nahsoR | G12: =IF(AND(D12=1,F12=1),1,"")
G13: =SUM(G8:G12) -> 0
A14: Group C | B14: E01A | C14: seekaV | E14: ayahT | G14: =IF(AND(D14=1,F14=1),1,"")
A15: Group C | B15: E02/E09 | C15: naramuK | E15: senihT | G15: =IF(AND(D15=1,F15=1),1,"")
A16: Group C | B16: E03 | C16: htnahsarP | E16: regnahS | G16: =IF(AND(D16=1,F16=1),1,"")
A17: Group C | B17: E07 | C17: lukoK | E17: naveejaS | G17: =IF(AND(D17=1,F17=1),1,"")
A18: Group C | B18: E90A | C18: ivaR | E18: ardneevaN | G18: =IF(AND(D18=1,F18=1),1,"")
G19: =SUM(G14:G18) -> 0
A20: Group D | B20: E87/E94 | C20: nahteenavaN | E20: nasebaS | G20: =IF(AND(D20=1,F20=1),1,"")
A21: Group D | B21: E89/E96 | C21: nalavaliN | E21: ecnerwaL | G21: =IF(AND(D21=1,F21=1),1,"")
A22: Group D | B22: E90B | C22: ramukavaN | E22: nahseihtaS | G22: =IF(AND(D22=1,F22=1),1,"")
A23: Group D | B23: E91A | C23: nayihtaS | E23: navahtA | G23: =IF(AND(D23=1,F23=1),1,"")
A24: Group D | B24: E93/S95 | C24: najaK | E24: naheJ | G24: =IF(AND(D24=1,F24=1),1,"")
G25: =SUM(G20:G24) -> 0
A26: Women & Boys | B26: LA-TH | C26: ajnavaL | E26: ayinarahT | G26: =IF(AND(D26=1,F26=1),1,"")
A27: Women & Boys | B27: NE-VI | C27: hseleN | E27: nahtrihiV | G27: =IF(AND(D27=1,F27=1),1,"")
A28: Women & Boys | B28: NI-AS | C28: nahsoriN | E28: niwhsA | G28: =IF(AND(D28=1,F28=1),1,"")
A29: Women & Boys | B29: SO-AA | C29: ayrooS | E29: naylihaA | G29: =IF(AND(D29=1,F29=1),1,"")
G30: =SUM(G26:G29) -> 0
A31: Girls | B31: AL | C31: anahcrA | E31: akemskaL | G31: =IF(AND(D31=1,F31=1),1,"")
A32: Girls | B32: HA | C32: iniraH | E32: ajnanA | G32: =IF(AND(D32=1,F32=1),1,"")
A33: Girls | B33: SA | C33: anahtaS | E33: arimhskA | G33: =IF(AND(D33=1,F33=1),1,"")
A34: Girls | B34: TS | C34: akihsunahT | E34: anahaS | G34: =IF(AND(D34=1,F34=1),1,"")
G35: =SUM(G31:G34) -> 0

Sheet quali_schedule
A1: NOT AVAILABLE YET

Sheet quali_score
A1: NOT AVAILABLE YET

Sheet quali_results
A2: g1
A3: g2
A4: g3
A5: g4
A8: a1 | B8: NOT AVAILABLE YET
A9: a2
A10: a3
A11: a4
A12: a5
A15: b1
A16: b2
A17: b3
A18: b4
A19: b5
A22: c1
A23: c2
A24: c3
... A39: w4

Sheet knockout_score
A1: Gold
B3: =VLOOKUP("a1", quali_results!$A$1:$C$40,2,0) -> NOT AVAILABLE YET | C3: =VLOOKUP("a1", quali_results!$A$1:$C$40,3,0) -> 0 | G3: =SUM(D3>D4,E3>E4,F3>F4) -> 0
B4: =VLOOKUP("c2", quali_results!$A$1:$C$40,2,0) -> 0 | C4: =VLOOKUP("c2", quali_results!$A$1:$C$40,3,0) -> 0 | G4: =SUM(D3<D4,E3<E4,F3<F4) -> 0
I5: =IF($G3>$G4,B3,IF($G3<$G4,B4,"")) | J5: =IF($G3>$G4,C3,IF($G3<$G4,C4,"")) | N5: =SUM(K5>K6,L5>L6,M5>M6) -> 0
I6: =IF($G7>$G8,B7,IF($G7<$G8,B8,"")) | J6: =IF($G7>$G8,C7,IF($G7<$G8,C8,"")) | N6: =SUM(K5<K6,L5<L6,M5<M6) -> 0
B7: =VLOOKUP("a2", quali_results!$A$1:$C$40,2,0) -> 0 | C7: =VLOOKUP("a2", quali_results!$A$1:$C$40,3,0) -> 0 | G7: =SUM(D7>D8,E7>E8,F7>F8) -> 0
B8: =VLOOKUP("c1", quali_results!$A$1:$C$40,2,0) -> 0 | C8: =VLOOKUP("c1", quali_results!$A$1:$C$40,3,0) -> 0 | G8: =SUM(D7<D8,E7<E8,F7<F8) -> 0 | P8: =IF($N5>$N6,I5,IF($N5<$N6,I6,"")) | Q8: =IF($N5>$N6,J5,IF($N5<$N6,J6,"")) | U8: =SUM(R8>R9,S8>S9,T8>T9) -> 0
P9: =IF($N13>$N14,I13,IF($N13<$N14,I14,"")) | Q9: =IF($N13>$N14,J13,IF($N13<$N14,J14,"")) | U9: =SUM(R8<R9,S8<S9,T8<T9) -> 0
B11: =VLOOKUP("b1", quali_results!$A$1:$C$40,2,0) -> 0 | C11: =VLOOKUP("b1", quali_results!$A$1:$C$40,3,0) -> 0 | G11: =SUM(D11>D12,E11>E12,F11>F12) -> 0 | P11: =IF($N5>$N6,I6,IF($N5<$N6,I5,"")) | Q11: =IF($N5>$N6,J6,IF($N5<$N6,J5,"")) | U11: =SUM(R11>R12,S11>S12,T11>T12) -> 0
B12: =VLOOKUP("d2", quali_results!$A$1:$C$40,2,0) -> 0 | C12: =VLOOKUP("d2", quali_results!$A$1:$C$40,3,0) -> 0 | G12: =SUM(D11<D12,E11<E12,F11<F12) -> 0 | P12: =IF($N13>$N14,I14,IF($N13<$N14,I13,"")) | Q12: =IF($N13>$N14,J14,IF($N13<$N14,J13,"")) | U12: =SUM(R11<R12,S11<S12,T11<T12) -> 0
I13: =IF($G11>$G12,B11,IF($G11<$G12,B12,"")) | J13: =IF($G11>$G12,C11,IF($G11<$G12,C12,"")) | N13: =SUM(K13>K14,L13>L14,M13>M14) -> 0
I14: =IF($G15>$G16,B15,IF($G15<$G16,B16,"")) | J14: =IF($G15>$G16,C15,IF($G15<$G16,C16,"")) | N14: =SUM(K13<K14,L13<L14,M13<M14) -> 0
B15: =VLOOKUP("b2", quali_results!$A$1:$C$40,2,0) -> 0 | C15: =VLOOKUP("b2", quali_results!$A$1:$C$40,3,0) -> 0 | G15: =SUM(D15>D16,E15>E16,F15>F16) -> 0
B16: =VLOOKUP("d1", quali_results!$A$1:$C$40,2,0) -> 0 | C16: =VLOOKUP("d1", quali_results!$A$1:$C$40,3,0) -> 0 | G16: =SUM(D15<D16,E15<E16,F15<F16) -> 0
A19: Silver
P21: =VLOOKUP("a3", quali_results!$A$1:$C$40,2,0) -> 0 | Q21: =VLOOKUP("a3", quali_results!$A$1:$C$40,3,0) -> 0 | U21: =SUM(R21>R22,S21>S22,T21>T22) -> 0
P22: =IF($G11>$G12,B12,IF($G11<$G12,B11,"")) | Q22: =IF($G11>$G12,C12,IF($G11<$G12,C11,"")) | U22: =SUM(R21<R22,S21<S22,T21<T22) -> 0
W23: =IF($U21>$U22,P21,IF($U21<$U22,P22,"")) | X23: =IF($U21>$U22,Q21,IF($U21<$U22,Q22,"")) | AB23: =SUM(Y23>Y24,Z23>Z24,AA23>AA24) -> 0
W24: =IF($U25>$U26,P25,IF($U25<$U26,P26,"")) | X24: =IF($U25>$U26,Q25,IF($U25<$U26,Q26,"")) | AB24: =SUM(Y23<Y24,Z23<Z24,AA23<AA24) -> 0
P25: =VLOOKUP("b3", quali_results!$A$1:$C$40,2,0) -> 0 | Q25: =VLOOKUP("b3", quali_results!$A$1:$C$40,3,0) -> 0 | U25: =SUM(R25>R26,S25>S26,T25>T26) -> 0
P26: =IF($G3>$G4,B4,IF($G3<$G4,B3,"")) | Q26: =IF($G3>$G4,C4,IF($G3<$G4,C3,"")) | U26: =SUM(R25<R26,S25<S26,T25<T26) -> 0 | AD26: =IF($AB23>$AB24,W23,IF($AB23<$AB24,W24,"")) | AE26: =IF($AB23>$AB24,X23,IF($AB23<$AB24,X24,"")) | AI26: =SUM(AF26>AF27,AG26>AG27,AH26>AH27) -> 0
AD27: =IF($AB31>$AB32,W31,IF($AB31<$AB32,W32,"")) | AE27: =IF($AB31>$AB32,X31,IF($AB31<$AB32,X32,"")) | AI27: =SUM(AF26<AF27,AG26<AG27,AH26<AH27) -> 0
P29: =VLOOKUP("c3", quali_results!$A$1:$C$40,2,0) -> 0 | Q29: =VLOOKUP("c3", quali_results!$A$1:$C$40,3,0) -> 0 | U29: =SUM(R29>R30,S29>S30,T29>T30) -> 0 | AD29: =IF($AB23>$AB24,W24,IF($AB23<$AB24,W23,"")) | AE29: =IF($AB23>$AB24,X24,IF($AB23<$AB24,X23,"")) | AI29: =SUM(AF29>AF30,AG29>AG30,AH29>AH30) -> 0
P30: =IF($G15>$G16,B16,IF($G15<$G16,B15,"")) | Q30: =IF($G15>$G16,C16,IF($G15<$G16,C15,"")) | U30: =SUM(R29<R30,S29<S30,T29<T30) -> 0 | AD30: =IF($AB31>$AB32,W32,IF($AB31<$AB32,W31,"")) | AE30: =IF($AB31>$AB32,X32,IF($AB31<$AB32,X31,"")) | AI30: =SUM(AF29<AF30,AG29<AG30,AH29<AH30) -> 0
W31: =IF($U29>$U30,P29,IF($U29<$U30,P30,"")) | X31: =IF($U29>$U30,Q29,IF($U29<$U30,Q30,"")) | AB31: =SUM(Y31>Y32,Z31>Z32,AA31>AA32) -> 0
W32: =IF($U33>$U34,P33,IF($U33<$U34,P34,"")) | X32: =IF($U33>$U34,Q33,IF($U33<$U34,Q34,"")) | AB32: =SUM(Y31<Y32,Z31<Z32,AA31<AA32) -> 0
P33: =VLOOKUP("d3", quali_results!$A$1:$C$40,2,0) -> 0 | Q33: =VLOOKUP("d3", quali_results!$A$1:$C$40,3,0) -> 0 | U33: =SUM(R33>R34,S33>S34,T33>T34) -> 0
P34: =IF($G7>$G8,B8,IF($G7<$G8,B7,"")) | Q34: =IF($G7>$G8,C8,IF($G7<$G8,C7,"")) | U34: =SUM(R33<R34,S33<S34,T33<T34) -> 0
A37: Bronze
W39: =VLOOKUP("a4", quali_results!$A$1:$C$40,2,0) -> 0 | X39: =VLOOKUP("a4", quali_results!$A$1:$C$40,3,0) -> 0 | AB39: =SUM(Y39>Y40,Z39>Z40,AA39>AA40) -> 0
W40: =IF($U21>$U22,P22,IF($U21<$U22,P21,"")) | X40: =IF($U21>$U22,Q22,IF($U21<$U22,Q21,"")) | AB40: =SUM(Y39<Y40,Z39<Z40,AA39<AA40) -> 0
AD41: =IF($AB39>$AB40,W39,IF($AB39<$AB40,W40,"")) | AE41: =IF($AB39>$AB40,X39,IF($AB39<$AB40,X40,"")) | AI41: =SUM(AF41>AF42,AG41>AG42,AH41>AH42) -> 0
AD42: =IF($AB43>$AB44,W43,IF($AB43<$AB44,W44,"")) | AE42: =IF($AB43>$AB44,X43,IF($AB43<$AB44,X44,"")) | AI42: =SUM(AF41<AF42,AG41<AG42,AH41<AH42) -> 0
W43: =VLOOKUP("b4", quali_results!$A$1:$C$40,2,0) -> 0 | X43: =VLOOKUP("b4", quali_results!$A$1:$C$40,3,0) -> 0 | AB43: =SUM(Y43>Y44,Z43>Z44,AA43>AA44) -> 0
W44: =IF($U25>$U26,P26,IF($U25<$U26,P25,"")) | X44: =IF($U25>$U26,Q26,IF($U25<$U26,Q25,"")) | AB44: =SUM(Y43<Y44,Z43<Z44,AA43<AA44) -> 0 | AK44: =IF($AI41>$AI42,AD41,IF($AI41<$AI42,AD42,"")) | AL44: =IF($AI41>$AI42,AE41,IF($AI41<$AI42,AE42,"")) | AP44: =SUM(AM44>AM45,AN44>AN45,AO44>AO45) -> 0
AK45: =IF($AI49>$AI50,AD49,IF($AI49<$AI50,AD50,"")) | AL45: =IF($AI49>$AI50,AE49,IF($AI49<$AI50,AE50,"")) | AP45: =SUM(AM44<AM45,AN44<AN45,AO44<AO45) -> 0
W47: =VLOOKUP("c4", quali_results!$A$1:$C$40,2,0) -> 0 | X47: =VLOOKUP("c4", quali_results!$A$1:$C$40,3,0) -> 0 | AB47: =SUM(Y47>Y48,Z47>Z48,AA47>AA48) -> 0 | AK47: =IF($AI41>$AI42,AD42,IF($AI41<$AI42,AD41,"")) | AL47: =IF($AI41>$AI42,AE42,IF($AI41<$AI42,AE41,"")) | AP47: =SUM(AM47>AM48,AN47>AN48,AO47>AO48) -> 0
W48: =IF($U29>$U30,P30,IF($U29<$U30,P29,"")) | X48: =IF($U29>$U30,Q30,IF($U29<$U30,Q29,"")) | AB48: =SUM(Y47<Y48,Z47<Z48,AA47<AA48) -> 0 | AK48: =IF($AI49>$AI50,AD50,IF($AI49<$AI50,AD49,"")) | AL48: =IF($AI49>$AI50,AE50,IF($AI49<$AI50,AE49,"")) | AP48: =SUM(AM47<AM48,AN47<AN48,AO47<AO48) -> 0
AD49: =IF($AB47>$AB48,W47,IF($AB47<$AB48,W48,"")) | AE49: =IF($AB47>$AB48,X47,IF($AB47<$AB48,X48,"")) | AI49: =SUM(AF49>AF50,AG49>AG50,AH49>AH50) -> 0
AD50: =IF($AB51>$AB52,W51,IF($AB51<$AB52,W52,"")) | AE50: =IF($AB51>$AB52,X51,IF($AB51<$AB52,X52,"")) | AI50: =SUM(AF49<AF50,AG49<AG50,AH49<AH50) -> 0
...

Sheet final_results
A1: Girls
A2: =IF(knockout_score!$N80>knockout_score!$N81,knockout_score!I80,IF(knockout_score!$N80<knockout_score!$N81,knockout_score!I81,"")) | B2: =IF(knockout_score!$N80>knockout_score!$N81,knockout_score!J80,IF(knockout_score!$N80<knockout_score!$N81,knockout_score!J81,""))
A3: =IF(knockout_score!$N80>knockout_score!$N81,knockout_score!I81,IF(knockout_score!$N80<knockout_score!$N81,knockout_score!I80,"")) | B3: =IF(knockout_score!$N80>knockout_score!$N81,knockout_score!J81,IF(knockout_score!$N80<knockout_score!$N81,knockout_score!J80,""))
A4: =IF(knockout_score!$N83>knockout_score!$N84,knockout_score!I83,IF(knockout_score!$N83<knockout_score!$N84,knockout_score!I84,"")) | B4: =IF(knockout_score!$N83>knockout_score!$N84,knockout_score!J83,IF(knockout_score!$N83<knockout_score!$N84,knockout_score!J84,""))
A5: =IF(knockout_score!$N83>knockout_score!$N84,knockout_score!I84,IF(knockout_score!$N83<knockout_score!$N84,knockout_score!I83,"")) | B5: =IF(knockout_score!$N83>knockout_score!$N84,knockout_score!J84,IF(knockout_score!$N83<knockout_score!$N84,knockout_score!J83,""))
A7: Women & Boys
A8: =IF(knockout_score!$N62>knockout_score!$N63,knockout_score!I62,IF(knockout_score!$N62<knockout_score!$N63,knockout_score!I63,"")) | B8: =IF(knockout_score!$N62>knockout_score!$N63,knockout_score!J62,IF(knockout_score!$N62<knockout_score!$N63,knockout_score!J63,""))
A9: =IF(knockout_score!$N62>knockout_score!$N63,knockout_score!I63,IF(knockout_score!$N62<knockout_score!$N63,knockout_score!I62,"")) | B9: =IF(knockout_score!$N62>knockout_score!$N63,knockout_score!J63,IF(knockout_score!$N62<knockout_score!$N63,knockout_score!J62,""))
A10: =IF(knockout_score!$N65>knockout_score!$N66,knockout_score!I65,IF(knockout_score!$N65<knockout_score!$N66,knockout_score!I66,"")) | B10: =IF(knockout_score!$N65>knockout_score!$N66,knockout_score!J65,IF(knockout_score!$N65<knockout_score!$N66,knockout_score!J66,""))
A11: =IF(knockout_score!$N65>knockout_score!$N66,knockout_score!I66,IF(knockout_score!$N65<knockout_score!$N66,knockout_score!I65,"")) | B11: =IF(knockout_score!$N65>knockout_score!$N66,knockout_score!J66,IF(knockout_score!$N65<knockout_score!$N66,knockout_score!J65,""))
A13: Gold
A14: =IF(knockout_score!$U8>knockout_score!$U9,knockout_score!P8,IF(knockout_score!$U8<knockout_score!$U9,knockout_score!P9,"")) | B14: =IF(knockout_score!$U8>knockout_score!$U9,knockout_score!Q8,IF(knockout_score!$U8<knockout_score!$U9,knockout_score!Q9,""))
A15: =IF(knockout_score!$U8>knockout_score!$U9,knockout_score!P9,IF(knockout_score!$U8<knockout_score!$U9,knockout_score!P8,"")) | B15: =IF(knockout_score!$U8>knockout_score!$U9,knockout_score!Q9,IF(knockout_score!$U8<knockout_score!$U9,knockout_score!Q8,""))
A16: =IF(knockout_score!$U11>knockout_score!$U12,knockout_score!P11,IF(knockout_score!$U11<knockout_score!$U12,knockout_score!P12,"")) | B16: =IF(knockout_score!$U11>knockout_score!$U12,knockout_score!Q11,IF(knockout_score!$U11<knockout_score!$U12,knockout_score!Q12,""))
A17: =IF(knockout_score!$U11>knockout_score!$U12,knockout_score!P12,IF(knockout_score!$U11<knockout_score!$U12,knockout_score!P11,"")) | B17: =IF(knockout_score!$U11>knockout_score!$U12,knockout_score!Q12,IF(knockout_score!$U11<knockout_score!$U12,knockout_score!Q11,""))
A19: Silver
A20: =IF(knockout_score!$AI26>knockout_score!$AI27,knockout_score!AD26,IF(knockout_score!$AI26<knockout_score!$AI27,knockout_score!AD27,"")) | B20: =IF(knockout_score!$AI26>knockout_score!$AI27,knockout_score!AE26,IF(knockout_score!$AI26<knockout_score!$AI27,knockout_score!AE27,""))
A21: =IF(knockout_score!$AI26>knockout_score!$AI27,knockout_score!AD27,IF(knockout_score!$AI26<knockout_score!$AI27,knockout_score!AD26,"")) | B21: =IF(knockout_score!$AI26>knockout_score!$AI27,knockout_score!AE27,IF(knockout_score!$AI26<knockout_score!$AI27,knockout_score!AE26,""))
A22: =IF(knockout_score!$AI29>knockout_score!$AI30,knockout_score!AD29,IF(knockout_score!$AI29<knockout_score!$AI30,knockout_score!AD30,"")) | B22: =IF(knockout_score!$AI29>knockout_score!$AI30,knockout_score!AE29,IF(knockout_score!$AI29<knockout_score!$AI30,knockout_score!AE30,""))
A23: =IF(knockout_score!$AI29>knockout_score!$AI30,knockout_score!AD30,IF(knockout_score!$AI29<knockout_score!$AI30,knockout_score!AD29,"")) | B23: =IF(knockout_score!$AI29>knockout_score!$AI30,knockout_score!AE30,IF(knockout_score!$AI29<knockout_score!$AI30,knockout_score!AE29,""))
A25: Bronze
A26: =IF(knockout_score!$AP44>knockout_score!$AP45,knockout_score!AK44,IF(knockout_score!$AP44<knockout_score!$AP45,knockout_score!AK45,"")) | B26: =IF(knockout_score!$AP44>knockout_score!$AP45,knockout_score!AL44,IF(knockout_score!$AP44<knockout_score!$AP45,knockout_score!AL45,""))
A27: =IF(knockout_score!$AP44>knockout_score!$AP45,knockout_score!AK45,IF(knockout_score!$AP44<knockout_score!$AP45,knockout_score!AK44,"")) | B27: =IF(knockout_score!$AP44>knockout_score!$AP45,knockout_score!AL45,IF(knockout_score!$AP44<knockout_score!$AP45,knockout_score!AL44,""))
A28: =IF(knockout_score!$AP47>knockout_score!$AP48,knockout_score!AK47,IF(knockout_score!$AP47<knockout_score!$AP48,knockout_score!AK48,"")) | B28: =IF(knockout_score!$AP47>knockout_score!$AP48,knockout_score!AL47,IF(knockout_score!$AP47<knockout_score!$AP48,knockout_score!AL48,""))
A29: =IF(knockout_score!$AP47>knockout_score!$AP48,knockout_score!AK48,IF(knockout_score!$AP47<knockout_score!$AP48,knockout_score!AK47,"")) | B29: =IF(knockout_score!$AP47>knockout_score!$AP48,knockout_score!AL48,IF(knockout_score!$AP47<knockout_score!$AP48,knockout_score!AL47,""))
A31: Participants
A32: =IF(knockout_score!$AB39>knockout_score!$AB40,knockout_score!W40,IF(knockout_score!$AB39<knockout_score!$AB40,knockout_score!W39,"")) | B32: =IF(knockout_score!$AB39>knockout_score!$AB40,knockout_score!X40,IF(knockout_score!$AB39<knockout_score!$AB40,knockout_score!X39,""))
A33: =IF(knockout_score!$AB43>knockout_score!$AB44,knockout_score!W44,IF(knockout_score!$AB43<knockout_score!$AB44,knockout_score!W43,"")) | B33: =IF(knockout_score!$AB43>knockout_score!$AB44,knockout_score!X44,IF(knockout_score!$AB43<knockout_score!$AB44,knockout_score!X43,""))
A34: =IF(knockout_score!$AB47>knockout_score!$AB48,knockout_score!W48,IF(knockout_score!$AB47<knockout_score!$AB48,knockout_score!W47,"")) | B34: =IF(knockout_score!$AB47>knockout_score!$AB48,knockout_score!X48,IF(knockout_score!$AB47<knockout_score!$AB48,knockout_score!X47,""))
A35: =IF(knockout_score!$AB51>knockout_score!$AB52,knockout_score!W52,IF(knockout_score!$AB51<knockout_score!$AB52,knockout_score!W51,"")) | B35: =IF(knockout_score!$AB51>knockout_score!$AB52,knockout_score!X52,IF(knockout_score!$AB51<knockout_score!$AB52,knockout_score!X51,""))
A36: =VLOOKUP("a5", quali_results!$A$1:$C$40,2,0) -> 0 | B36: =VLOOKUP("a5", quali_results!$A$1:$C$40,3,0) -> 0
A37: =VLOOKUP("b5", quali_results!$A$1:$C$40,2,0) -> 0 | B37: =VLOOKUP("b5", quali_results!$A$1:$C$40,3,0) -> 0
A38: =VLOOKUP("c5", quali_results!$A$1:$C$40,2,0) -> 0 | B38: =VLOOKUP("c5", quali_results!$A$1:$C$40,3,0) -> 0
A39: =VLOOKUP("d5", quali_results!$A$1:$C$40,2,0) -> 0 | B39: =VLOOKUP("d5", quali_results!$A$1:$C$40,3,0) -> 0
